
[2025-07-02T18:52:04.081690] Python REPL Error:
Code:
print("""
# Google广告活动地理统计数据质量分析报告

## 数据概览
- 数据集大小: 10,000行 x 32列
- 数据日期: 2022-12-19
- 数据内容: Google广告活动的地理位置统计数据，包含点击、展示、转化等指标

## 主要数据质量问题

### 1. 缺失值问题
- customer_name: 31条记录缺失 (0.31%)
- country: 8条记录缺失 (0.08%)
- 缺失值比例较低，对整体分析影响有限

### 2. 重复值问题
- 完全重复的行: 31条记录 (0.31%)
- 重复记录比例较低，但应在分析前删除以避免统计偏差

### 3. 数据一致性问题
- 点击数大于展示数: 12条记录
- 转化数大于点击数: 7条记录
- 有展示但无成本: 5,971条记录 (59.71%)
- 数据一致性问题中，"有展示但无成本"的比例较高，需要特别关注

### 4. 异常值问题
- cost_per_conversion超过1,000,000: 244条记录
- clicks超过1,000: 18条记录
- impressions超过100,000: 14条记录
- cost_per_conversion存在极端异常值，可能会严重影响平均值计算

### 5. 编码和特殊字符问题
- customer_name包含非ASCII字符: 581条记录 (5.81%)
- campaign_name包含特殊字符: 3,734条记录 (37.34%)
- 特殊字符问题较为普遍，尤其是campaign_name列

### 6. 非标准国家代码问题
- 非标准国家代码: 43条记录 (0.43%)
- 包括数字代码和缺失值

### 7. 零值比例高的问题
- clicks为0: 7,215条记录 (72.15%)
- impressions为0: 6条记录 (0.06%)
- cost为0: 5,974条记录 (59.74%)
- conversions为0: 9,430条记录 (94.30%)
- clicks和conversions的零值比例非常高，这是广告数据的常见特征，但需要在分析时特别处理

## 数据清洗成果
- 删除了31条重复记录
- 填充了所有缺失值
- 标记了12条点击数大于展示数的异常记录
- 标记了7条转化数大于点击数的异常记录
- 对244条cost_per_conversion异常值进行了上限处理
- 清理了580条customer_name中的非ASCII字符
- 标准化了35条非标准国家代码
- 转换了data_day列为datetime类型
- 新增了ctr(点击率)、cvr(转化率)和cpc(每次点击成本)等派生特征

## 建议

### 数据收集和存储建议
1. 加强数据验证规则，防止录入不一致的数据（如点击数大于展示数）
2. 统一字符编码标准，避免非ASCII字符问题
3. 标准化国家代码，使用ISO标准代码
4. 建立campaign_name的命名规范，减少特殊字符使用

### 数据分析建议
1. 对于cost_per_conversion等指标，考虑使用中位数而非平均值，或进行对数转换
2. 分析转化数据时，考虑使用零膨胀模型处理高比例的零值
3. 对于有展示但无成本的记录，可能需要单独分析或确认是否为免费展示
4. 在计算CTR、CVR等比率指标时，注意处理分母为零的情况

### 数据可视化建议
1. 使用箱线图展示数值型变量分布，识别异常值
2. 使用热力图展示国家、设备、网络等维度的广告效果
3. 对cost_per_conversion等高度偏斜的指标，使用对数刻度进行可视化

### 后续数据质量监控建议
1. 建立自动化数据质量检查流程，定期监控异常值和一致性问题
2. 设置数据质量阈值警报，及时发现数据异常
3. 记录数据清洗过程，确保分析结果可重现
""")

# 创建一个简单的数据质量评分卡
print("\n## 数据质量评分卡")
print("| 质量维度 | 得分(1-10) | 主要问题 |")
print("|---------|-----------|---------|")
print("| 完整性   | 9         | 缺失值比例低，仅有少量customer_name和country缺失 |")
print("| 唯一性   | 9         | 重复记录比例低，仅0.31% |")
print("| 一致性   | 5         | 有展示但无成本比例高(59.71%)，存在点击>展示和转化>点击的记录 |")
print("| 准确性   | 6         | cost_per_conversion存在极端值，可能影响统计分析 |")
print("| 有效性   | 7         | 非标准国家代码和编码问题需要处理 |")
print("| 时效性   | 10        | 数据为单日数据，时效性好 |")
print("| 总体评分  | 7.7       | 数据质量中上，经过适当清洗后可用于分析 |")
Error:
Traceback (most recent call last):
  File "/Users/lht/home/venv/lib/python3.13/site-packages/strands_tools/python_repl.py", line 293, in start
    exec(code, namespace)
    ~~~~^^^^^^^^^^^^^^^^^
  File "<string>", line 1, in <module>
  File "/Users/lht/home/venv/lib/python3.13/site-packages/streamlit/web/bootstrap.py", line 44, in signal_handler
    server.stop()
    ~~~~~~~~~~~^^
  File "/Users/lht/home/venv/lib/python3.13/site-packages/streamlit/web/server/server.py", line 469, in stop
    cli_util.print_to_cli("  Stopping...", fg="blue")
    ~~~~~~~~~~~~~~~~~~~~~^^^^^^^^^^^^^^^^^^^^^^^^^^^^
  File "/Users/lht/home/venv/lib/python3.13/site-packages/streamlit/cli_util.py", line 34, in print_to_cli
    click.secho(message, **kwargs)
    ~~~~~~~~~~~^^^^^^^^^^^^^^^^^^^
  File "/Users/lht/home/venv/lib/python3.13/site-packages/click/termui.py", line 634, in secho
    return echo(message, file=file, nl=nl, err=err, color=color)
  File "/Users/lht/home/venv/lib/python3.13/site-packages/click/utils.py", line 318, in echo
    file.write(out)  # type: ignore
    ~~~~~~~~~~^^^^^
RuntimeError: reentrant call inside <_io.BufferedWriter name='<stdout>'>

During handling of the above exception, another exception occurred:

Traceback (most recent call last):
  File "/Users/lht/home/venv/lib/python3.13/site-packages/strands_tools/python_repl.py", line 500, in python_repl
    pty_mgr.start(code)
    ~~~~~~~~~~~~~^^^^^^
  File "/Users/lht/home/venv/lib/python3.13/site-packages/strands_tools/python_repl.py", line 298, in start
    traceback.print_exc(file=sys.stderr)
    ~~~~~~~~~~~~~~~~~~~^^^^^^^^^^^^^^^^^
  File "/opt/homebrew/Cellar/python@3.13/3.13.1/Frameworks/Python.framework/Versions/3.13/lib/python3.13/traceback.py", line 208, in print_exc
    print_exception(sys.exception(), limit=limit, file=file, chain=chain)
    ~~~~~~~~~~~~~~~^^^^^^^^^^^^^^^^^^^^^^^^^^^^^^^^^^^^^^^^^^^^^^^^^^^^^^
  File "/opt/homebrew/Cellar/python@3.13/3.13.1/Frameworks/Python.framework/Versions/3.13/lib/python3.13/traceback.py", line 130, in print_exception
    te.print(file=file, chain=chain, colorize=colorize)
    ~~~~~~~~^^^^^^^^^^^^^^^^^^^^^^^^^^^^^^^^^^^^^^^^^^^
  File "/opt/homebrew/Cellar/python@3.13/3.13.1/Frameworks/Python.framework/Versions/3.13/lib/python3.13/traceback.py", line 1455, in print
    print(line, file=file, end="")
    ~~~~~^^^^^^^^^^^^^^^^^^^^^^^^^
OSError: [Errno 5] Input/output error

